data/alpaca_sample.json
[{"T":"o","S":"BTC/USD","t":"2026-02-14T13:51:36.973856163Z","b":[{"p":69398.2,"s":1.2718},{"p":69383.04,"s":2.5777},{"p":69333.693,"s":3.82584},{"p":69285.3,"s":5.07244},{"p":69137.24,"s":6.365},{"p":68656.22,"s":0.000147605},{"p":68343.78,"s":0.000211841},{"p":68336.65,"s":7.70822},{"p":68263.542,"s":0.000355666},{"p":68000,"s":0.5},{"p":67881.773399014,"s":0.075},{"p":67811.782,"s":0.000470449},{"p":67276.127,"s":8.8876},{"p":66995.073891625,"s":0.00185},{"p":66324.48,"s":10.1596},{"p":65245.173516,"s":0.000398496},{"p":65024.630541871,"s":2.5557065},{"p":64926.108374384,"s":0.0054},{"p":64876.84729064,"s":0.0013},{"p":64827.586206896,"s":0.03},{"p":64532.019704433,"s":0.0308},{"p":64507.670891038,"s":0.000015502},{"p":64162.561576354,"s":0.0025},{"p":64146.798029556,"s":0.015361},{"p":64039.408866995,"s":0.4094481},{"p":63929.064039408,"s":0.002},{"p":63546.798029556,"s":0.01},{"p":63339.410102963,"s":0.000015787},{"p":63054.187192118,"s":0.03936},{"p":62498.522167487,"s":0.00793},{"p":62315.27093596,"s":0.03955},{"p":62068.965517241,"s":0.07847},{"p":62000,"s":0.000323},{"p":61871.921182266,"s":0.0032},{"p":61576.354679802,"s":0.03},{"p":61083.743842364,"s":0.534},{"p":60098.522167487,"s":0.02794},{"p":60050,"s":0.0042},{"p":60000,"s":0.06},{"p":59605.911330049,"s":0.0065},{"p":59235.467980295,"s":0.017185},{"p":59150.738916256,"s":0.1},{"p":59118.226600985,"s":0.0025},{"p":59113.30049261,"s":0.2919633},{"p":58620.689655172,"s":0.02},{"p":58128.078817733,"s":1.1},{"p":58038.953610096,"s":0.000017229},{"p":58000,"s":0.09},{"p":57873.141024636,"s":0.00002972},{"p":57261.083743842,"s":0.02},{"p":57142.857142857,"s":0.0162},{"p":56157.63546798,"s":0.14},{"p":55172.413793103,"s":0.0135},{"p":54192.1182266,"s":0.0025},{"p":54187.192118226,"s":1.011},{"p":53211.63546798,"s":0.01852},{"p":53201.970443349,"s":0.3},{"p":52216.748768472,"s":0.006405},{"p":52069.722884167,"s":0.000029767},{"p":52000,"s":0.03},{"p":51563.588109955,"s":0.000019393},{"p":50000,"s":0.0001},{"p":49261.083743842,"s":0.032},{"p":46260.340285177,"s":0.000029615},{"p":45094.870829013,"s":0.000022175},{"p":40456.922144708,"s":0.000029661},{"p":34647.539545719,"s":0.000029727},{"p":25537.931034482,"s":0.15},{"p":88.669950738,"s":10},{"p":84.502463054,"s":4},{"p":0.985221674,"s":1}],"a":[{"p":69477.2,"s":2.58094},{"p":69484.43,"s":1.274},{"p":69512.5,"s":3.807},{"p":69585.9,"s":5.14356},{"p":69718.4,"s":6.4453},{"p":70525.21,"s":7.70485},{"p":71472.081218274,"s":0.1},{"p":71616.004,"s":8.924},{"p":72569.91,"s":10.271},{"p":72639.55,"s":0.000200088},{"p":73096.446700507,"s":0.0056},{"p":75500,"s":0.005362704},{"p":76142.131979695,"s":0.032851038},{"p":78680.203045685,"s":1},{"p":79832.487309644,"s":0.095},{"p":80000,"s":0.00229405},{"p":80150,"s":0.022},{"p":83248.730964467,"s":0.015392693},{"p":84000,"s":1.24111813},{"p":84263.959390862,"s":0.001302923},{"p":85279.187817258,"s":0.007},{"p":86142.131979695,"s":0.37746601},{"p":86294.416243654,"s":0.00433578},{"p":87500,"s":0.001997},{"p":89000,"s":0.090183305},{"p":89847.71573604,"s":0.05},{"p":92385.78680203,"s":0.103234343},{"p":93401.015228426,"s":0.001301175},{"p":94923.85786802,"s":0.000202133},{"p":96446.700507614,"s":0.056587645},{"p":98000,"s":0.00994},{"p":98477.157360406,"s":0.0074},{"p":100000,"s":0.01},{"p":100507.614213197,"s":0.005},{"p":101279,"s":0.000075065},{"p":101522.842639593,"s":0.01440872},{"p":102538.071065989,"s":0.002980925},{"p":106598.984771573,"s":0.025009305},{"p":111675.126903553,"s":0.037176815},{"p":115000,"s":0.01},{"p":116430.33,"s":0.005},{"p":116440.92,"s":0.005},{"p":116780.72,"s":0.005},{"p":117280.72,"s":0.005},{"p":117572.83825999017,"s":0.033324508},{"p":117780.72,"s":0.005},{"p":118280.72,"s":0.005},{"p":118780.72,"s":0.005},{"p":119280.72,"s":0.005},{"p":119289.340101522,"s":0.035217093},{"p":119780.72,"s":0.005},{"p":120280.72,"s":0.005},{"p":120780.72,"s":0.005},{"p":121280.72,"s":0.005},{"p":121780.72,"s":0.005},{"p":122280.72,"s":0.005},{"p":122780.72,"s":0.005},{"p":123280.72,"s":0.005},{"p":123780.72,"s":0.005},{"p":124280.72,"s":0.005},{"p":124780.72,"s":0.005},{"p":124873.0964467,"s":0.010573257},{"p":125280.72,"s":0.005},{"p":125780.72,"s":0.005},{"p":126280.72,"s":0.005},{"p":127000,"s":0.01},{"p":127918.781725888,"s":0.0061},{"p":130000,"s":0.05777303},{"p":131979.695431472,"s":0.006950236},{"p":132994.923857868,"s":0.039},{"p":142131.979695431,"s":0.005},{"p":147208.121827411,"s":0.0021},{"p":152284.26395939,"s":0.041641206},{"p":177664.974619289,"s":0.005799118}],"r":true}]
[{"T":"o","S":"BTC/USD","t":"2026-02-14T13:51:41.828486701Z","b":[{"p":69398.2,"s":0}],"a":[]}]
[{"T":"o","S":"BTC/USD","t":"2026-02-14T13:51:41.828872961Z","b":[{"p":69380.1,"s":1.28298}],"a":[]}]
[{"T":"o","S":"BTC/USD","t":"2026-02-14T13:51:41.828884601Z","b":[],"a":[{"p":69477.2,"s":0}]}]
[{"T":"o","S":"BTC/USD","t":"2026-02-14T13:51:41.829056221Z","b":[],"a":[{"p":69468.71,"s":1.289}]}]
[{"T":"o","S":"BTC/USD","t":"2026-02-14T13:51:41.829090801Z","b":[{"p":69383.04,"s":0}],"a":[]}]
[{"T":"o","S":"BTC/USD","t":"2026-02-14T13:51:41.829213371Z","b":[{"p":69379.392,"s":2.57}],"a":[]}]
[{"T":"o","S":"BTC/USD","t":"2026-02-14T13:51:41.829313411Z","b":[],"a":[{"p":69484.43,"s":0}]}]
[{"T":"o","S":"BTC/USD","t":"2026-02-14T13:51:41.829398851Z","b":[],"a":[{"p":69482.3,"s":2.55}]}]
[{"T":"o","S":"BTC/USD","t":"2026-02-14T13:51:41.829633401Z","b":[{"p":69333.693,"s":0}],"a":[]}]
[{"T":"o","S":"BTC/USD","t":"2026-02-14T13:51:41.829751491Z","b":[{"p":69331.111,"s":3.848}],"a":[]}]
[{"T":"o","S":"BTC/USD","t":"2026-02-14T13:51:41.829774261Z","b":[],"a":[{"p":69512.5,"s":0}]}]
[{"T":"o","S":"BTC/USD","t":"2026-02-14T13:51:41.829870381Z","b":[],"a":[{"p":69509.67,"s":3.80383}]}]
[{"T":"o","S":"BTC/USD","t":"2026-02-14T13:51:41.829998251Z","b":[{"p":69285.3,"s":0}],"a":[]}]
[{"T":"o","S":"BTC/USD","t":"2026-02-14T13:51:41.830127851Z","b":[{"p":69248.056,"s":5.158}],"a":[]}]
[{"T":"o","S":"BTC/USD","t":"2026-02-14T13:51:41.830217501Z","b":[],"a":[{"p":69585.9,"s":0}]}]
[{"T":"o","S":"BTC/USD","t":"2026-02-14T13:51:41.830278451Z","b":[],"a":[{"p":69588.003,"s":5.15435}]}]
[{"T":"o","S":"BTC/USD","t":"2026-02-14T13:51:41.830366221Z","b":[{"p":69137.24,"s":0}],"a":[]}]
[{"T":"o","S":"BTC/USD","t":"2026-02-14T13:51:41.830470441Z","b":[{"p":69160.9,"s":6.344}],"a":[]}]
[{"T":"o","S":"BTC/USD","t":"2026-02-14T13:51:41.830594531Z","b":[],"a":[{"p":69718.4,"s":0}]}]
[{"T":"o","S":"BTC/USD","t":"2026-02-14T13:51:41.830639771Z","b":[],"a":[{"p":69723.4,"s":6.4273}]}]
[{"T":"o","S":"BTC/USD","t":"2026-02-14T13:51:41.830728761Z","b":[{"p":68336.65,"s":0}],"a":[]}]
[{"T":"o","S":"BTC/USD","t":"2026-02-14T13:51:41.830772721Z","b":[{"p":68315.14,"s":7.70511}],"a":[]}]
[{"T":"o","S":"BTC/USD","t":"2026-02-14T13:51:41.830850061Z","b":[],"a":[{"p":70525.21,"s":0}]}]
[{"T":"o","S":"BTC/USD","t":"2026-02-14T13:51:41.830974591Z","b":[],"a":[{"p":70531.816,"s":7.6602}]}]
[{"T":"o","S":"BTC/USD","t":"2026-02-14T13:51:41.831055871Z","b":[{"p":67276.127,"s":0}],"a":[]}]
[{"T":"o","S":"BTC/USD","t":"2026-02-14T13:51:41.831126921Z","b":[{"p":67261,"s":8.9777}],"a":[]}]
[{"T":"o","S":"BTC/USD","t":"2026-02-14T13:51:41.831193911Z","b":[],"a":[{"p":71616.004,"s":0}]}]
[{"T":"o","S":"BTC/USD","t":"2026-02-14T13:51:41.831261591Z","b":[],"a":[{"p":71598.1,"s":8.9266}]}]
[{"T":"o","S":"BTC/USD","t":"2026-02-14T13:51:41.831379081Z","b":[{"p":66324.48,"s":0}],"a":[]}]
[{"T":"o","S":"BTC/USD","t":"2026-02-14T13:51:41.831467451Z","b":[{"p":66304.4,"s":10.1714}],"a":[]}]
[{"T":"o","S":"BTC/USD","t":"2026-02-14T13:51:41.831596201Z","b":[],"a":[{"p":72569.91,"s":0}]}]
[{"T":"o","S":"BTC/USD","t":"2026-02-14T13:51:41.831677221Z","b":[],"a":[{"p":72565.78,"s":10.261}]}]
[{"T":"o","S":"BTC/USD","t":"2026-02-14T13:51:41.940134261Z","b":[{"p":69380.1,"s":0}],"a":[]}]
[{"T":"o","S":"BTC/USD","t":"2026-02-14T13:51:41.940268451Z","b":[{"p":69386.95,"s":1.27247}],"a":[]}]
[{"T":"o","S":"BTC/USD","t":"2026-02-14T13:51:41.940583571Z","b":[],"a":[{"p":69468.71,"s":0}]}]
[{"T":"o","S":"BTC/USD","t":"2026-02-14T13:51:41.940734221Z","b":[],"a":[{"p":69458.238,"s":1.279}]}]
