data/alpaca_sample2.json
[{"T":"o","S":"BTC/USD","t":"2025-10-25T21:03:38.165488575Z","b":[{"p":111304.1,"s":2.9353},{"p":111303.6,"s":1.4781},{"p":111202.5,"s":4.401},{"p":110990.47,"s":5.86276},{"p":110524.8,"s":7.31179},{"p":109685.79,"s":8.86},{"p":109489,"s":0.00346},{"p":108808,"s":0.00348},{"p":108719.21182266,"s":0.001},{"p":108371.11879342733,"s":0.000180398},{"p":108346.4345788056,"s":0.000429086},{"p":108128,"s":0.0035},{"p":107965.21,"s":10.26},{"p":106900,"s":0.00021},{"p":106600.985221674,"s":0.0033},{"p":106445.4,"s":11.89},{"p":106403.940886699,"s":0.048},{"p":106194.08866995,"s":0.0027},{"p":106157.63546798,"s":0.002},{"p":106000,"s":0.03},{"p":105911.330049261,"s":0.002},{"p":105418.719211822,"s":0.00183},{"p":105320.197044334,"s":0.000273999},{"p":105000,"s":0.01},{"p":104980.295566502,"s":0.001},{"p":104926.108374384,"s":0.006},{"p":104433.497536945,"s":0.1},{"p":104000,"s":0.01349623},{"p":103940.886699507,"s":0.21584},{"p":103449.261083743,"s":0.01},{"p":103448.275862068,"s":0.0868762},{"p":102955.66502463,"s":0.02},{"p":102857.142857142,"s":0.005},{"p":102660.098522167,"s":0.0005},{"p":102463.054187192,"s":0.022599},{"p":102250,"s":0.0213},{"p":101970.443349753,"s":0.000373},{"p":101500,"s":0.02},{"p":101477.832512315,"s":0.016},{"p":101000,"s":0.03},{"p":100500,"s":0.25},{"p":100000,"s":0.5},{"p":99507.389162561,"s":0.001},{"p":98522.167487684,"s":0.1770087},{"p":98500,"s":0.5},{"p":98325.123152709,"s":0.0015},{"p":97536.945812807,"s":0.0065},{"p":94581.280788177,"s":0.006},{"p":93596.0591133,"s":0.0007},{"p":88669.950738916,"s":0.03},{"p":86699.507389162,"s":0.005},{"p":83743.842364532,"s":0.005},{"p":70935.960591133,"s":0.01},{"p":68965.517241379,"s":0.03},{"p":12012.807881773,"s":0.00093},{"p":50.837438423,"s":1},{"p":4.926108374,"s":8},{"p":2.955665024,"s":0.4},{"p":0.985221674,"s":3}],"a":[{"p":111563.6,"s":1.478},{"p":111606.3,"s":2.96594},{"p":111708.15,"s":4.38948},{"p":111939.995,"s":5.89405},{"p":112389.24,"s":7.3203},{"p":112607.76511,"s":0.000250623},{"p":112636.5,"s":0.804},{"p":112690.355329949,"s":0.014775172},{"p":113201.43,"s":8.898},{"p":113705.583756345,"s":0.09802201},{"p":114280.72,"s":0.005},{"p":114780.72,"s":0.005},{"p":114921.5,"s":10.26},{"p":115280.72,"s":0.005},{"p":115761.421319796,"s":0.002},{"p":115780.72,"s":0.005},{"p":116000,"s":0.00149775},{"p":116243.654822335,"s":0.01},{"p":116280.72,"s":0.005},{"p":116430.33,"s":0.005},{"p":116440.92,"s":0.005},{"p":116476.94,"s":11.7582},{"p":116751.269035532,"s":0.018098266},{"p":116780.72,"s":0.005},{"p":117280.72,"s":0.005},{"p":117575.33583607357,"s":0.033324508},{"p":117780.72,"s":0.005},{"p":118280.72,"s":0.004836713},{"p":118780.72,"s":0.005},{"p":119280.72,"s":0.005},{"p":119780.72,"s":0.005},{"p":119796.95431472,"s":0.009803609},{"p":120000,"s":0.003835083},{"p":120203.610749101,"s":0.000080649},{"p":120280.72,"s":0.005},{"p":120667.535441413,"s":0.00005111},{"p":120780.72,"s":0.005},{"p":120812.182741116,"s":0.007953763},{"p":121280.72,"s":0.005},{"p":121780.72,"s":0.005},{"p":121827.411167512,"s":0.024614226},{"p":122280.72,"s":0.005},{"p":122780.72,"s":0.005},{"p":123280.72,"s":0.005},{"p":123780.72,"s":0.004094},{"p":123857.868020304,"s":0.0044},{"p":124280.72,"s":0.005},{"p":124780.72,"s":0.005},{"p":124873.0964467,"s":0.054},{"p":124974.61928934,"s":0.001158764},{"p":125050,"s":0.01},{"p":125280.72,"s":0.004884378},{"p":125370.558375634,"s":0.048931474},{"p":125380.710659898,"s":0.010646125},{"p":125500,"s":0.081877},{"p":125780.72,"s":0.005},{"p":125888.324873096,"s":0.0012},{"p":126000,"s":0.3},{"p":126280.72,"s":0.005},{"p":126780.72,"s":0.01},{"p":126903.553299492,"s":0.225809594},{"p":127918.781725888,"s":0.056397621},{"p":128221.41,"s":0.01},{"p":128934.010152284,"s":0.020717311},{"p":129949.23857868,"s":0.05},{"p":130000,"s":0.05777303},{"p":131979.695431472,"s":0.072723146},{"p":133959.390862944,"s":0.0015},{"p":136040.609137055,"s":0.07},{"p":137055.837563451,"s":0.20086035},{"p":137721.4,"s":0.0009975},{"p":138578.680203045,"s":1},{"p":140000,"s":0.0001},{"p":142131.979695431,"s":0.003628151},{"p":147208.121827411,"s":0.001},{"p":150253.807106598,"s":1.305306012},{"p":152284.26395939,"s":0.199025208},{"p":162436.54822335,"s":0.001}],"r":true}]
[{"T":"o","S":"BTC/USD","t":"2025-10-25T21:05:00.731494754Z","b":[{"p":111304.1,"s":0}],"a":[]}]
[{"T":"o","S":"BTC/USD","t":"2025-10-25T21:05:00.731552644Z","b":[{"p":111357.623,"s":1.4713}],"a":[]}]
[{"T":"o","S":"BTC/USD","t":"2025-10-25T21:05:00.731565374Z","b":[],"a":[{"p":111563.6,"s":0}]}]
[{"T":"o","S":"BTC/USD","t":"2025-10-25T21:05:00.731573714Z","b":[],"a":[{"p":111542,"s":1.467}]}]
[{"T":"o","S":"BTC/USD","t":"2025-10-25T21:05:00.731663614Z","b":[{"p":111303.6,"s":0}],"a":[]}]
[{"T":"o","S":"BTC/USD","t":"2025-10-25T21:05:00.731679834Z","b":[{"p":111282.33,"s":2.9565}],"a":[]}]
[{"T":"o","S":"BTC/USD","t":"2025-10-25T21:05:00.731754504Z","b":[],"a":[{"p":111606.3,"s":0}]}]
[{"T":"o","S":"BTC/USD","t":"2025-10-25T21:05:00.731778704Z","b":[],"a":[{"p":111604.4,"s":2.955}]}]
[{"T":"o","S":"BTC/USD","t":"2025-10-25T21:05:00.731796064Z","b":[{"p":111202.5,"s":0}],"a":[]}]
[{"T":"o","S":"BTC/USD","t":"2025-10-25T21:05:00.731994664Z","b":[{"p":111158.36,"s":4.374}],"a":[]}]
[{"T":"o","S":"BTC/USD","t":"2025-10-25T21:05:00.732004864Z","b":[],"a":[{"p":111708.15,"s":0}]}]
[{"T":"o","S":"BTC/USD","t":"2025-10-25T21:05:00.732012104Z","b":[],"a":[{"p":111721.8,"s":4.396}]}]
[{"T":"o","S":"BTC/USD","t":"2025-10-25T21:05:00.732073044Z","b":[{"p":110990.47,"s":0}],"a":[]}]
[{"T":"o","S":"BTC/USD","t":"2025-10-25T21:05:00.732136864Z","b":[{"p":110962.27,"s":5.935}],"a":[]}]
[{"T":"o","S":"BTC/USD","t":"2025-10-25T21:05:00.732143814Z","b":[],"a":[{"p":111939.995,"s":0}]}]
[{"T":"o","S":"BTC/USD","t":"2025-10-25T21:05:00.732166434Z","b":[],"a":[{"p":111943.26,"s":5.871}]}]
[{"T":"o","S":"BTC/USD","t":"2025-10-25T21:05:00.732213344Z","b":[{"p":110524.8,"s":0}],"a":[]}]
[{"T":"o","S":"BTC/USD","t":"2025-10-25T21:05:00.732263484Z","b":[{"p":110504.81,"s":7.311}],"a":[]}]
[{"T":"o","S":"BTC/USD","t":"2025-10-25T21:05:00.732269974Z","b":[],"a":[{"p":112389.24,"s":0}]}]
[{"T":"o","S":"BTC/USD","t":"2025-10-25T21:05:00.732313154Z","b":[],"a":[{"p":112329.5,"s":7.327}]}]
[{"T":"o","S":"BTC/USD","t":"2025-10-25T21:05:00.732317424Z","b":[{"p":109685.79,"s":0}],"a":[]}]
[{"T":"o","S":"BTC/USD","t":"2025-10-25T21:05:00.732356334Z","b":[{"p":109649.43,"s":8.8759}],"a":[]}]
[{"T":"o","S":"BTC/USD","t":"2025-10-25T21:05:00.732494254Z","b":[],"a":[{"p":113201.43,"s":0}]}]
[{"T":"o","S":"BTC/USD","t":"2025-10-25T21:05:00.732502724Z","b":[],"a":[{"p":113224.41,"s":8.7702}]}]
[{"T":"o","S":"BTC/USD","t":"2025-10-25T21:05:00.732513524Z","b":[{"p":107965.21,"s":0}],"a":[]}]
[{"T":"o","S":"BTC/USD","t":"2025-10-25T21:05:00.732526434Z","b":[{"p":107941.93,"s":10.359}],"a":[]}]
[{"T":"o","S":"BTC/USD","t":"2025-10-25T21:05:00.732615234Z","b":[],"a":[{"p":114921.5,"s":0}]}]
[{"T":"o","S":"BTC/USD","t":"2025-10-25T21:05:00.732677914Z","b":[],"a":[{"p":114948.5,"s":10.3}]}]
[{"T":"o","S":"BTC/USD","t":"2025-10-25T21:05:00.732684124Z","b":[{"p":106445.4,"s":0}],"a":[]}]
[{"T":"o","S":"BTC/USD","t":"2025-10-25T21:05:00.732793724Z","b":[{"p":106441.502,"s":11.7426}],"a":[]}]
[{"T":"o","S":"BTC/USD","t":"2025-10-25T21:05:00.732801674Z","b":[],"a":[{"p":116476.94,"s":0}]}]
[{"T":"o","S":"BTC/USD","t":"2025-10-25T21:05:00.732824784Z","b":[],"a":[{"p":116438.99,"s":11.688}]}]
